Workbook

Sheet Pop_2022_2023
A1: Région | B1: Pop 2021 | C1: Structure 2021 | D1: Pop 2022 | E1: Structure 2022 | F1: Pop 2023
A2: Batha | B2: 709820.81 | C2: 0.042205032 | D2: 722960.25 | E2: 0.042205032 | F2: 761114.32
A3: Borkou | B3: 142104.1 | C3: 0.008449327 | D3: 144734.58 | E3: 0.008449327 | F3: 152372.92
A4: Chari Baguirmi | B4: 869571.78 | C4: 0.051703619 | D4: 885668.36 | E4: 0.051703619 | F4: 932409.31
A5: Guéra | B5: 654242.96 | C5: 0.038900444 | D5: 666353.6 | E5: 0.038900444 | F5: 701520.26
A6: Hadjer Lamis | B6: 846044.34 | C6: 0.050304708 | D6: 861705.4 | E6: 0.050304708 | F6: 907181.72
A7: Kanem | B7: 512703.76 | C7: 0.030484706 | D7: 522194.38 | E7: 0.030484706 | F7: 549753.07
A8: Lac | B8: 657165.24 | C8: 0.039074199 | D8: 669329.97 | E8: 0.039074199 | F8: 704653.71
A9: Logone Occidental | B9: 1062456.7 | C9: 0.063172306 | D9: 1082123.7 | E9: 0.063172306 | F9: 1139232.6
A10: Logone Oriental | B10: 1194793.8 | C10: 0.0710409 | D10: 1216910.5 | E10: 0.0710409 | F10: 1281132.7
A11: Mandoul | B11: 955198.71 | C11: 0.056794886 | D11: 972880.32 | E11: 0.056794886 | F11: 1024223.9
A12: Mayo Kebbi Est | B12: 1179900.4 | C12: 0.070155361 | D12: 1201741.5 | E12: 0.070155361 | F12: 1265163.1
A13: Mayo Kebbi Ouest | B13: 869881.5 | C13: 0.051722035 | D13: 885983.81 | E13: 0.051722035 | F13: 932741.41
... A25: Control | B25: 16818393 | C25: 1 | D25: 17129717 | E25: 1 | F25: 18033734
A26: Tchad | F26: 18033734

Sheet ProjPop20_21_22_23admin2
A1: admin2Pcode | B1: admin2Name_fr | C1: admin2RefName | D1: admin1Pcode | E1: admin1Name_fr | F1: Proj2016_Hommes | G1: Proj2016_Femmes | H1: Proj2016_Total | I1: Proj2017_Hommes | J1: Proj2017_Femmes | K1: Proj2017_Total | L1: Proj2018_Hommes | M1: Proj2018_Femmes | N1: Proj2018_Total | O1: Proj2019_Hommes | P1: Proj2019_Femmes | Q1: Proj2019_Total | R1: Proj2020_Hommes | S1: Proj2020_Femmes | T1: Proj_2020_Total | U1: Proj2021_Hommes | V1: Proj2021_Femmes | W1: Proj_2021_Total | X1: Proj2022_Hommes | Y1: Proj2022_Femmes | Z1: Proj_2022_Tota4 | AA1: Proj2023_Hommes2 | AB1: Proj2032_Femmes3 | AC1: Proj_2023_Tota44
A2: TD0101 | B2: Batha Ouest | C2: Batha Ouest | D2: TD01 | E2: Batha | F2: 125463 | G2: 128277 | H2: 253741 | I2: 125406 | J2: 128217 | K2: 253624 | L2: 129423 | M2: 132325 | N2: 261749 | O2: 133623 | P2: 136619 | Q2: 270242 | R2: 138064 | S2: 141159 | T2: 279223 | U2: 154132.29 | V2: 145248.64 | W2: 287312.61 | X2: 144693.71 | Y2: 147937.33 | Z2: 292631.04 | AA2: 152329.89 | AB2: 155744.69 | AC2: 308074.57
A3: TD0102 | B3: Batha Est | C3: Batha Est | D3: TD01 | E3: Batha | F3: 107365 | G3: 124085 | H3: 231450 | I3: 107315 | J3: 124028 | K3: 231343 | L3: 110753 | M3: 128001 | N3: 238754 | O3: 114346 | P3: 132155 | Q3: 246501 | R3: 118146 | S3: 136547 | T3: 254693 | U3: 131896.17 | V3: 140503.02 | W3: 262071.93 | X3: 123819.26 | Y3: 143103.86 | Z3: 266923.13 | AA3: 130353.8 | AB3: 150656.14 | AC3: 281009.94
A4: TD0103 | B4: Fitri | C4: Fitri | D4: TD01 | E4: Batha | F4: 69296 | G4: 72394 | H4: 141690 | I4: 69265 | J4: 72360 | K4: 141625 | L4: 71483 | M4: 74678 | N4: 146161 | O4: 73803 | P4: 77101 | Q4: 150904 | R4: 76256 | S4: 79663 | T4: 155919 | U4: 85130.895 | V4: 81970.986 | W4: 160436.27 | X4: 79917.744 | Y4: 83488.345 | Z4: 163406.09 | AA4: 84135.385 | AB4: 87894.424 | AC4: 172029.81
A5: TD0201 | B5: Borkou | C5: Borkou | D5: TD02 | E5: Borkou | F5: 47162 | G5: 40583 | H5: 87745 | I5: 49087 | J5: 42239 | K5: 91326 | L5: 50763 | M5: 43682 | N5: 94445 | O5: 52479 | P5: 45158 | Q5: 97637 | R5: 54229 | S5: 46665 | T5: 100894 | U5: 55800.116 | V5: 48016.973 | W5: 103817.09 | X5: 56833.027 | Y5: 48905.811 | Z5: 105738.84 | AA5: 59832.378 | AB5: 51486.804 | AC5: 111319.18
A6: TD0202 | B6: Borkou Yala | C6: Borkou Yala | D6: TD02 | E6: Borkou | F6: 16988 | G6: 15371 | H6: 32359 | I6: 17681 | J6: 15998 | K6: 33679 | L6: 18285 | M6: 16545 | N6: 34830 | O6: 18903 | P6: 17104 | Q6: 36007 | R6: 19534 | S6: 17675 | T6: 37209 | U6: 20099.937 | V6: 18187.078 | W6: 38287.014 | X6: 20472.005 | Y6: 18523.738 | Z6: 38995.743 | AA6: 21552.411 | AB6: 19501.324 | AC6: 41053.734
A7: TD0301 | B7: Baguirmi | C7: Baguirmi | D7: TD03 | E7: Chari-Baguirmi | F7: 135091 | G7: 134062 | H7: 269153 | I7: 138679 | J7: 137621 | K7: 276300 | L7: 143514 | M7: 142420 | N7: 285934 | O7: 148545 | P7: 147412 | Q7: 295957 | R7: 153789 | S7: 152617 | T7: 306406 | U7: 158244.56 | V7: 157038.6 | W7: 315283.16 | X7: 161173.81 | Y7: 159945.53 | Z7: 321119.34 | AA7: 169679.72 | AB7: 168386.62 | AC7: 338066.34
A8: TD0302 | B8: Chari | C8: Chari | D8: TD03 | E8: Chari-Baguirmi | F8: 115724 | G8: 119011 | H8: 234735 | I8: 118797 | J8: 122172 | K8: 240969 | L8: 122939 | M8: 126431 | N8: 249370 | O8: 127249 | P8: 130863 | Q8: 258112 | R8: 131741 | S8: 135483 | T8: 267224 | U8: 135557.78 | V8: 139408.2 | W8: 274965.98 | X8: 138067.08 | Y8: 141988.77 | Z8: 280055.85 | AA8: 145353.54 | AB8: 149482.2 | AC8: 294835.74
A9: TD0303 | B9: Loug-Chari | C9: Loug-Chari | D9: TD03 | E9: Chari-Baguirmi | F9: 117519 | G9: 120935 | H9: 238454 | I9: 120641 | J9: 124146 | K9: 244787 | L9: 124847 | M9: 128475 | N9: 253322 | O9: 129223 | P9: 132978 | Q9: 262201 | R9: 133785 | S9: 137673 | T9: 271458 | U9: 137661 | V9: 141661.64 | W9: 279322.65 | X9: 140209.23 | Y9: 144283.93 | Z9: 284493.17 | AA9: 147608.75 | AB9: 151898.49 | AC9: 299507.23
A10: TD0401 | B10: Guéra | C10: Guera | D10: TD04 | E10: Guera | F10: 108267 | G10: 113049 | H10: 221316 | I10: 94089 | J10: 98246 | K10: 192335 | L10: 95727 | M10: 99956 | N10: 195683 | O10: 97496 | P10: 101804 | Q10: 199300 | R10: 99632 | S10: 104034 | T10: 203666 | U10: 102518.53 | V10: 107048.06 | W10: 209566.59 | X10: 104416.24 | Y10: 109029.62 | Z10: 213445.86 | AA10: 109926.78 | AB10: 114783.63 | AC10: 224710.41
A11: TD0402 | B11: Abtouyour | C11: Abtouyour | D11: TD04 | E11: Guera | F11: 104673 | G11: 110208 | H11: 214881 | I11: 90967 | J11: 95777 | K11: 186744 | L11: 92550 | M11: 97444 | N11: 189994 | O11: 94260 | P11: 99245 | Q11: 193505 | R11: 96325 | S11: 101420 | T11: 197745 | U11: 99115.716 | V11: 104358.33 | W11: 203474.04 | X11: 100950.44 | Y11: 106290.1 | Z11: 207240.54 | AA11: 106278.08 | AB11: 111899.53 | AC11: 218177.61
A12: TD0403 | B12: Barh-Signaka | C12: Barh-Signaka | D12: TD04 | E12: Guera | F12: 65394 | G12: 67528 | H12: 132922 | I12: 56832 | J12: 58685 | K12: 115517 | L12: 57821 | M12: 59707 | N12: 117528 | O12: 58889 | P12: 60810 | Q12: 119700 | R12: 60180 | S12: 62142 | T12: 122322 | U12: 61923.527 | V12: 63942.37 | W12: 125865.9 | X12: 63069.789 | Y12: 65126.003 | Z12: 128195.79 | AA12: 66398.283 | AB12: 68563.013 | AC12: 134961.3
A13: TD0404 | B13: Mangalmé | C13: Mangalme | D13: TD04 | E13: Guera | F13: 56874 | G13: 64928 | H13: 121802 | I13: 49426 | J13: 56426 | K13: 105852 | L13: 50287 | M13: 57408 | N13: 107695 | O13: 51217 | P13: 58469 | Q13: 109686 | R13: 52339 | S13: 59750 | T13: 112089 | U13: 53855.359 | V13: 61481.069 | W13: 115336.43 | X13: 54852.271 | Y13: 62619.141 | Z13: 117471.41 | AA13: 57747.088 | AB13: 65923.852 | AC13: 123670.94
... A71: TD2303 | B71: Mourtcha | C71: Mourtcha | D71: TD23 | E71: Ennedi Ouest | F71: 15044 | G71: 12309 | H71: 27353 | I71: 15631 | J71: 12788 | K71: 28419 | L71: 16090 | M71: 13164 | N71: 29254 | O71: 16630 | P71: 13606 | Q71: 30236 | R71: 17193 | S71: 14067 | T71: 31260 | U71: 17691.113 | V71: 14474.547 | W71: 32165.661 | X71: 18018.592 | Y71: 14742.485 | Z71: 32761.077 | AA71: 18969.519 | AB71: 15520.516 | AC71: 34490.035

Sheet Calcul_projPop21_22_23admin2
K1: Structure 2020 | N1: Population 2021 | Q1: Structure 2021 | T1: Population 2022 | W1: Structure 2022 | Z1: Population 2023
A2: admin2Pcode | B2: admin2Name_fr | C2: admin2RefName | D2: admin1Pcode | E2: admin1Name_fr | F2: Proj2016_Hommes | G2: Proj2016_Femmes | H2: Proj2020_Hommes | I2: Proj2020_Femmes | J2: Proj_2020_Total | K2: Proj2020_Hommes2 | L2: Proj2020_Femmes3 | M2: Proj_2020_Total4 | N2: Proj2021_Hommes22 | O2: Proj2021_Femmes32 | P2: Proj_2021_Total43 | Q2: Proj2021_Hommes22 | R2: Proj2021_Femmes32 | S2: Proj_2021_Total43 | T2: Proj2022_Hommes22 | U2: Proj2022_Femmes32 | V2: Proj_2022_Total43 | W2: Proj2022_Hommes22 | X2: Proj2022_Femmes32 | Y2: Proj_2022_Total43 | Z2: Proj2023_Hommes22 | AA2: Proj2023_Femmes32 | AB2: Proj_2023_Total43
A3: TD0101 | B3: Batha Ouest | C3: Batha Ouest | D3: TD01 | E3: Batha | F3: 125463 | G3: 128277 | H3: 138064 | I3: 141159 | J3: 279223 | K3: =Table15[[#This Row],[Proj2020_Hommes]]/$J$6 -> 0.20014061 | L3: =+Table15[[#This Row],[Proj2020_Femmes]]/$J$6 -> 0.20462719 | M3: =+Table15[[#This Row],[Proj_2020_Total]]/$J$6 -> 0.40476781 | N3: =+Table15[[#This Row],[Proj2020_Hommes2]]*$N$7 -> 142063.97 | O3: =+Table15[[#This Row],[Proj2020_Femmes3]]*$N$7 -> 145248.64 | P3: =+Table15[[#This Row],[Proj_2020_Total4]]*$N$7 -> 287312.61 | Q3: =Table15[[#This Row],[Proj2021_Hommes22]]/$P$6 -> 0.20014061 | R3: =Table15[[#This Row],[Proj2021_Femmes32]]/$P$6 -> 0.20462719 | S3: =Table15[[#This Row],[Proj_2021_Total43]]/$P$6 -> 0.40476781 | T3: =Q3*$V$6 -> 144693.71 | U3: =R3*$V$6 -> 147937.33 | V3: =S3*$V$6 -> 292631.04 | W3: =T3/$V$6 -> 0.20014061 | X3: =U3/$V$6 -> 0.20462719 | Y3: =V3/$V$6 -> 0.40476781 | Z3: =W3*$AB$6 -> 152329.89 | AA3: =X3*$AB$6 -> 155744.69 | AB3: =Y3*$AB$6 -> 308074.57
A4: TD0102 | B4: Batha Est | C4: Batha Est | D4: TD01 | E4: Batha | F4: 107365 | G4: 124085 | H4: 118146 | I4: 136547 | J4: 254693 | K4: =Table15[[#This Row],[Proj2020_Hommes]]/$J$6 -> 0.17126704 | L4: =+Table15[[#This Row],[Proj2020_Femmes]]/$J$6 -> 0.19794154 | M4: =+Table15[[#This Row],[Proj_2020_Total]]/$J$6 -> 0.36920858 | N4: =+Table15[[#This Row],[Proj2020_Hommes2]]*$N$7 -> 121568.91 | O4: =+Table15[[#This Row],[Proj2020_Femmes3]]*$N$7 -> 140503.02 | P4: =+Table15[[#This Row],[Proj_2020_Total4]]*$N$7 -> 262071.93 | Q4: =Table15[[#This Row],[Proj2021_Hommes22]]/$P$6 -> 0.17126704 | R4: =Table15[[#This Row],[Proj2021_Femmes32]]/$P$6 -> 0.19794154 | S4: =Table15[[#This Row],[Proj_2021_Total43]]/$P$6 -> 0.36920858 | T4: =Q4*$V$6 -> 123819.26 | U4: =R4*$V$6 -> 143103.86 | V4: =S4*$V$6 -> 266923.13 | W4: =T4/$V$6 -> 0.17126704 | X4: =U4/$V$6 -> 0.19794154 | Y4: =V4/$V$6 -> 0.36920858 | Z4: =W4*$AB$6 -> 130353.8 | AA4: =X4*$AB$6 -> 150656.14 | AB4: =Y4*$AB$6 -> 281009.94
A5: TD0103 | B5: Fitri | C5: Fitri | D5: TD01 | E5: Batha | F5: 69296 | G5: 72394 | H5: 76256 | I5: 79663 | J5: 155919 | K5: =Table15[[#This Row],[Proj2020_Hommes]]/$J$6 -> 0.11054238 | L5: =+Table15[[#This Row],[Proj2020_Femmes]]/$J$6 -> 0.11548124 | M5: =+Table15[[#This Row],[Proj_2020_Total]]/$J$6 -> 0.22602361 | N5: =+Table15[[#This Row],[Proj2020_Hommes2]]*$N$7 -> 78465.279 | O5: =+Table15[[#This Row],[Proj2020_Femmes3]]*$N$7 -> 81970.986 | P5: =+Table15[[#This Row],[Proj_2020_Total4]]*$N$7 -> 160436.27 | Q5: =Table15[[#This Row],[Proj2021_Hommes22]]/$P$6 -> 0.11054238 | R5: =Table15[[#This Row],[Proj2021_Femmes32]]/$P$6 -> 0.11548124 | S5: =Table15[[#This Row],[Proj_2021_Total43]]/$P$6 -> 0.22602361 | T5: =Q5*$V$6 -> 79917.744 | U5: =R5*$V$6 -> 83488.345 | V5: =S5*$V$6 -> 163406.09 | W5: =T5/$V$6 -> 0.11054238 | X5: =U5/$V$6 -> 0.11548124 | Y5: =V5/$V$6 -> 0.22602361 | Z5: =W5*$AB$6 -> 84135.385 | AA5: =X5*$AB$6 -> 87894.424 | AB5: =Y5*$AB$6 -> 172029.81
J6: =+J3+J4+J5 -> 689835 | K6: =Table15[[#This Row],[Proj2020_Hommes]]/$J$19 -> 0 | L6: =+Table15[[#This Row],[Proj2020_Femmes]]/$J$6 -> 0 | M6: =+Table15[[#This Row],[Proj_2020_Total]]/$J$6 -> 1 | N6: =+Table15[[#This Row],[Proj2020_Hommes2]]*$N$7 -> 0 | O6: =+Table15[[#This Row],[Proj2020_Femmes3]]*$N$7 -> 0 | P6: =+Table15[[#This Row],[Proj_2020_Total4]]*$N$7 -> 709820.81 | V6: 722960.25 | AB6: 761114.32
N7: 709820.81
A8: TD0201 | B8: Borkou | C8: Borkou | D8: TD02 | E8: Borkou | F8: 47162 | G8: 40583 | H8: 54229 | I8: 46665 | J8: 100894 | K8: =Table15[[#This Row],[Proj2020_Hommes]]/$J$19 -> 0.085289594 | L8: =Table15[[#This Row],[Proj2020_Femmes]]/$J$10 -> 0.33789997 | M8: =Table15[[#This Row],[Proj_2020_Total]]/$J$10 -> 0.73057066 | N8: 55800.116 | O8: 48016.973 | P8: 103817.09 | Q8: =Table15[[#This Row],[Proj2021_Hommes22]]/$P$10 -> 0.39267069 | R8: =Table15[[#This Row],[Proj2021_Femmes32]]/$P$10 -> 0.33789997 | S8: =Table15[[#This Row],[Proj_2021_Total43]]/$P$10 -> 0.73057066 | T8: =Q8*$V$10 -> 56833.027 | U8: =R8*$V$10 -> 48905.811 | V8: =S8*$V$10 -> 105738.84 | W8: =T8/$V$10 -> 0.39267069 | X8: =U8/$V$10 -> 0.33789997 | Y8: =V8/$V$10 -> 0.73057066 | Z8: =W8*$AB$10 -> 59832.378 | AA8: =X8*$AB$10 -> 51486.804 | AB8: =Y8*$AB$10 -> 111319.18
A9: TD0202 | B9: Borkou Yala | C9: Borkou Yala | D9: TD02 | E9: Borkou | F9: 16988 | G9: 15371 | H9: 19534 | I9: 17675 | J9: 37209 | K9: =Table15[[#This Row],[Proj2020_Hommes]]/$J$19 -> 0.030722435 | L9: =Table15[[#This Row],[Proj2020_Femmes]]/$J$10 -> 0.12798419 | M9: =Table15[[#This Row],[Proj_2020_Total]]/$J$10 -> 0.26942934 | N9: 20099.937 | O9: 18187.078 | P9: 38287.014 | Q9: =Table15[[#This Row],[Proj2021_Hommes22]]/$P$10 -> 0.14144515 | R9: =Table15[[#This Row],[Proj2021_Femmes32]]/$P$10 -> 0.12798419 | S9: =Table15[[#This Row],[Proj_2021_Total43]]/$P$10 -> 0.26942934 | T9: =Q9*$V$10 -> 20472.005 | U9: =R9*$V$10 -> 18523.738 | V9: =S9*$V$10 -> 38995.743 | W9: =T9/$V$10 -> 0.14144515 | X9: =U9/$V$10 -> 0.12798419 | Y9: =V9/$V$10 -> 0.26942934 | Z9: =W9*$AB$10 -> 21552.411 | AA9: =X9*$AB$10 -> 19501.324 | AB9: =Y9*$AB$10 -> 41053.734
J10: =J9+J8 -> 138103 | N10: =[1]Sheet1!$D$27 -> 142104.1 | P10: =P9+P8 -> 142104.1 | V10: 144734.58 | AB10: 152372.92
A11: TD0301 | B11: Baguirmi | C11: Baguirmi | D11: TD03 | E11: Chari-Baguirmi | F11: 135091 | G11: 134062 | H11: 153789 | I11: 152617 | J11: 306406 | K11: =Table15[[#This Row],[Proj2020_Hommes]]/$J$19 -> 0.2418743 | L11: =Table15[[#This Row],[Proj2020_Femmes]]/$J$14 -> 0.18059303 | M11: =Table15[[#This Row],[Proj_2020_Total]]/$J$14 -> 0.36257289 | N11: 158244.56 | O11: 157038.6 | P11: 315283.16 | Q11: =Table15[[#This Row],[Proj2021_Hommes22]]/$P$14 -> 0.18197986 | R11: =Table15[[#This Row],[Proj2021_Femmes32]]/$P$14 -> 0.18059303 | S11: =Table15[[#This Row],[Proj_2021_Total43]]/$P$14 -> 0.36257289 | T11: =Q11*$V$14 -> 161173.81 | U11: =R11*$V$14 -> 159945.53 | V11: =S11*$V$14 -> 321119.34 | W11: =T11/$V$14 -> 0.18197986 | X11: =U11/$V$14 -> 0.18059303 | Y11: =V11/$V$14 -> 0.36257289 | Z11: =W11*$AB$14 -> 169679.72 | AA11: =X11*$AB$14 -> 168386.62 | AB11: =Y11*$AB$14 -> 338066.34
A12: TD0302 | B12: Chari | C12: Chari | D12: TD03 | E12: Chari-Baguirmi | F12: 115724 | G12: 119011 | H12: 131741 | I12: 135483 | J12: 267224 | K12: =Table15[[#This Row],[Proj2020_Hommes]]/$J$19 -> 0.20719793 | L12: =Table15[[#This Row],[Proj2020_Femmes]]/$J$14 -> 0.16031822 | M12: =Table15[[#This Row],[Proj_2020_Total]]/$J$14 -> 0.31620849 | N12: 135557.78 | O12: 139408.2 | P12: 274965.98 | Q12: =Table15[[#This Row],[Proj2021_Hommes22]]/$P$14 -> 0.15589027 | R12: =Table15[[#This Row],[Proj2021_Femmes32]]/$P$14 -> 0.16031822 | S12: =Table15[[#This Row],[Proj_2021_Total43]]/$P$14 -> 0.31620849 | T12: =Q12*$V$14 -> 138067.08 | U12: =R12*$V$14 -> 141988.77 | V12: =S12*$V$14 -> 280055.85 | W12: =T12/$V$14 -> 0.15589027 | X12: =U12/$V$14 -> 0.16031822 | Y12: =V12/$V$14 -> 0.31620849 | Z12: =W12*$AB$14 -> 145353.54 | AA12: =X12*$AB$14 -> 149482.2 | AB12: =Y12*$AB$14 -> 294835.74
A13: TD0303 | B13: Loug-Chari | C13: Loug-Chari | D13: TD03 | E13: Chari-Baguirmi | F13: 117519 | G13: 120935 | H13: 133785 | I13: 137673 | J13: 271458 | K13: =Table15[[#This Row],[Proj2020_Hommes]]/$J$19 -> 0.21041266 | L13: =Table15[[#This Row],[Proj2020_Femmes]]/$J$14 -> 0.16290966 | M13: =Table15[[#This Row],[Proj_2020_Total]]/$J$14 -> 0.32121862 | N13: 137661 | O13: 141661.64 | P13: 279322.65 | Q13: =Table15[[#This Row],[Proj2021_Hommes22]]/$P$14 -> 0.15830896 | R13: =Table15[[#This Row],[Proj2021_Femmes32]]/$P$14 -> 0.16290966 | S13: =Table15[[#This Row],[Proj_2021_Total43]]/$P$14 -> 0.32121862 | T13: =Q13*$V$14 -> 140209.23 | U13: =R13*$V$14 -> 144283.93 | V13: =S13*$V$14 -> 284493.17 | W13: =T13/$V$14 -> 0.15830896 | X13: =U13/$V$14 -> 0.16290966 | Y13: =V13/$V$14 -> 0.32121862 | Z13: =W13*$AB$14 -> 147608.75 | AA13: =X13*$AB$14 -> 151898.49 | AB13: =Y13*$AB$14 -> 299507.23
J14: =J13+J12+J11 -> 845088 | N14: =[1]Sheet1!$D$28 -> 869571.78 | P14: =P13+P12+P11 -> 869571.78 | V14: 885668.36 | AB14: 932409.31
A15: TD0401 | B15: Guéra | C15: Guera | D15: TD04 | E15: Guera | F15: 108267 | G15: 113049 | H15: 99632 | I15: 104034 | J15: 203666 | K15: =Table15[[#This Row],[Proj2020_Hommes]]/$J$19 -> 0.15669794 | L15: =Table15[[#This Row],[Proj2020_Femmes]]/$J$19 -> 0.16362127 | M15: =Table15[[#This Row],[Proj_2020_Total]]/$J$19 -> 0.32031921 | N15: 102518.53 | O15: 107048.06 | P15: 209566.59 | Q15: =Table15[[#This Row],[Proj2021_Hommes22]]/$P$19 -> 0.15669794 | R15: =Table15[[#This Row],[Proj2021_Femmes32]]/$P$19 -> 0.16362127 | S15: =Table15[[#This Row],[Proj_2021_Total43]]/$P$19 -> 0.32031921 | T15: =Q15*$V$19 -> 104416.24 | U15: =R15*$V$19 -> 109029.62 | V15: =S15*$V$19 -> 213445.86 | W15: =T15/$V$19 -> 0.15669794 | X15: =U15/$V$19 -> 0.16362127 | Y15: =V15/$V$19 -> 0.32031921 | Z15: =W15*$AB$19 -> 109926.78 | AA15: =X15*$AB$19 -> 114783.63 | AB15: =Y15*$AB$19 -> 224710.41
A16: TD0402 | B16: Abtouyour | C16: Abtouyour | D16: TD04 | E16: Guera | F16: 104673 | G16: 110208 | H16: 96325 | I16: 101420 | J16: 197745 | K16: =Table15[[#This Row],[Proj2020_Hommes]]/$J$19 -> 0.1514968 | L16: =Table15[[#This Row],[Proj2020_Femmes]]/$J$19 -> 0.15951005 | M16: =Table15[[#This Row],[Proj_2020_Total]]/$J$19 -> 0.31100685 | N16: 99115.716 | O16: 104358.33 | P16: 203474.04 | Q16: =Table15[[#This Row],[Proj2021_Hommes22]]/$P$19 -> 0.1514968 | R16: =Table15[[#This Row],[Proj2021_Femmes32]]/$P$19 -> 0.15951005 | S16: =Table15[[#This Row],[Proj_2021_Total43]]/$P$19 -> 0.31100685 | T16: =Q16*$V$19 -> 100950.44 | U16: =R16*$V$19 -> 106290.1 | V16: =S16*$V$19 -> 207240.54 | W16: =T16/$V$19 -> 0.1514968 | X16: =U16/$V$19 -> 0.15951005 | Y16: =V16/$V$19 -> 0.31100685 | Z16: =W16*$AB$19 -> 106278.08 | AA16: =X16*$AB$19 -> 111899.53 | AB16: =Y16*$AB$19 -> 218177.61
A17: TD0403 | B17: Barh-Signaka | C17: Barh-Signaka | D17: TD04 | E17: Guera | F17: 65394 | G17: 67528 | H17: 60180 | I17: 62142 | J17: 122322 | K17: =Table15[[#This Row],[Proj2020_Hommes]]/$J$19 -> 0.094649131 | L17: =Table15[[#This Row],[Proj2020_Femmes]]/$J$19 -> 0.097734901 | M17: =Table15[[#This Row],[Proj_2020_Total]]/$J$19 -> 0.19238403 | N17: 61923.527 | O17: 63942.37 | P17: 125865.9 | Q17: =Table15[[#This Row],[Proj2021_Hommes22]]/$P$19 -> 0.094649131 | R17: =Table15[[#This Row],[Proj2021_Femmes32]]/$P$19 -> 0.097734901 | S17: =Table15[[#This Row],[Proj_2021_Total43]]/$P$19 -> 0.19238403 | T17: =Q17*$V$19 -> 63069.789 | U17: =R17*$V$19 -> 65126.003 | V17: =S17*$V$19 -> 128195.79 | W17: =T17/$V$19 -> 0.094649131 | X17: =U17/$V$19 -> 0.097734901 | Y17: =V17/$V$19 -> 0.19238403 | Z17: =W17*$AB$19 -> 66398.283 | AA17: =X17*$AB$19 -> 68563.013 | AB17: =Y17*$AB$19 -> 134961.3
A18: TD0404 | B18: Mangalmé | C18: Mangalme | D18: TD04 | E18: Guera | F18: 56874 | G18: 64928 | H18: 52339 | I18: 59750 | J18: 112089 | K18: =Table15[[#This Row],[Proj2020_Hommes]]/$J$19 -> 0.082317064 | L18: =Table15[[#This Row],[Proj2020_Femmes]]/$J$19 -> 0.093972841 | M18: =Table15[[#This Row],[Proj_2020_Total]]/$J$19 -> 0.17628991 | N18: 53855.359 | O18: 61481.069 | P18: 115336.43 | Q18: =Table15[[#This Row],[Proj2021_Hommes22]]/$P$19 -> 0.082317064 | R18: =Table15[[#This Row],[Proj2021_Femmes32]]/$P$19 -> 0.093972841 | S18: =Table15[[#This Row],[Proj_2021_Total43]]/$P$19 -> 0.17628991 | T18: =Q18*$V$19 -> 54852.271 | U18: =R18*$V$19 -> 62619.141 | V18: =S18*$V$19 -> 117471.41 | W18: =T18/$V$19 -> 0.082317064 | X18: =U18/$V$19 -> 0.093972841 | Y18: =V18/$V$19 -> 0.17628991 | Z18: =W18*$AB$19 -> 57747.088 | AA18: =X18*$AB$19 -> 65923.852 | AB18: =Y18*$AB$19 -> 123670.94
J19: =J18+J17+J16+J15 -> 635822 | N19: =[1]Sheet1!$D$29 -> 654242.96 | P19: =P18+P17+P16+P15 -> 654242.96 | V19: 666353.6 | AB19: 701520.26
A20: TD0501 | B20: Dagana | C20: Dagana | D20: TD05 | E20: Hadjer Lamis | F20: 146748 | G20: 146428 | H20: 136748 | I20: 136449 | J20: 273197 | K20: =Table15[[#This Row],[Proj2020_Hommes]]/$J$23 -> 0.16631518 | L20: =Table15[[#This Row],[Proj2020_Femmes]]/$J$23 -> 0.16595153 | M20: =Table15[[#This Row],[Proj_2020_Total]]/$J$23 -> 0.33226671 | N20: =Table15[[#This Row],[Proj2020_Hommes2]]*$N$23 -> 140710.02 | O20: =Table15[[#This Row],[Proj2020_Femmes3]]*$N$23 -> 140402.35 | P20: =Table15[[#This Row],[Proj_2020_Total4]]*$N$23 -> 281112.37 | Q20: =Table15[[#This Row],[Proj2021_Hommes22]]/$P$23 -> 0.16631518 | R20: =Table15[[#This Row],[Proj2021_Femmes32]]/$P$23 -> 0.16595153 | S20: =Table15[[#This Row],[Proj_2021_Total43]]/$P$23 -> 0.33226671 | T20: =Q20*$V$23 -> 143314.69 | U20: =R20*$V$23 -> 143001.33 | V20: =S20*$V$23 -> 286316.02 | W20: =T20/$V$23 -> 0.16631518 | X20: =U20/$V$23 -> 0.16595153 | Y20: =V20/$V$23 -> 0.33226671 | Z20: =W20*$AB$23 -> 150878.09 | AA20: =X20*$AB$23 -> 150548.19 | AB20: =Y20*$AB$23 -> 301426.29
A21: TD0502 | B21: Dababa | C21: Dababa | D21: TD05 | E21: Hadjer Lamis | F21: 119612 | G21: 122112 | H21: 163962 | I21: 167388 | J21: 331350 | K21: =Table15[[#This Row],[Proj2020_Hommes]]/$J$23 -> 0.1994133 | L21: =Table15[[#This Row],[Proj2020_Femmes]]/$J$23 -> 0.20358006 | M21: =Table15[[#This Row],[Proj_2020_Total]]/$J$23 -> 0.40299335 | N21: =Table15[[#This Row],[Proj2020_Hommes2]]*$N$23 -> 168712.49 | O21: =Table15[[#This Row],[Proj2020_Femmes3]]*$N$23 -> 172237.75 | P21: =Table15[[#This Row],[Proj_2020_Total4]]*$N$23 -> 340950.25 | Q21: =Table15[[#This Row],[Proj2021_Hommes22]]/$P$23 -> 0.1994133 | R21: =Table15[[#This Row],[Proj2021_Femmes32]]/$P$23 -> 0.20358006 | S21: =Table15[[#This Row],[Proj_2021_Total43]]/$P$23 -> 0.40299335 | T21: =Q21*$V$23 -> 171835.52 | U21: =R21*$V$23 -> 175426.03 | V21: =S21*$V$23 -> 347261.55 | W21: =T21/$V$23 -> 0.1994133 | X21: =U21/$V$23 -> 0.20358006 | Y21: =V21/$V$23 -> 0.40299335 | Z21: =W21*$AB$23 -> 180904.1 | AA21: =X21*$AB$23 -> 184684.1 | AB21: =Y21*$AB$23 -> 365588.2
A22: TD0503 | B22: Haraze-Al-Biar | C22: Haraze-Al-Biar | D22: TD05 | E22: Hadjer Lamis | F22: 97617 | G22: 94981 | H22: 110327 | I22: 107348 | J22: 217675 | K22: =Table15[[#This Row],[Proj2020_Hommes]]/$J$23 -> 0.13418152 | L22: =Table15[[#This Row],[Proj2020_Femmes]]/$J$23 -> 0.13055841 | M22: =Table15[[#This Row],[Proj_2020_Total]]/$J$23 -> 0.26473994 | N22: =Table15[[#This Row],[Proj2020_Hommes2]]*$N$23 -> 113523.52 | O22: =Table15[[#This Row],[Proj2020_Femmes3]]*$N$23 -> 110458.21 | P22: =Table15[[#This Row],[Proj_2020_Total4]]*$N$23 -> 223981.73 | Q22: =Table15[[#This Row],[Proj2021_Hommes22]]/$P$23 -> 0.13418152 | R22: =Table15[[#This Row],[Proj2021_Femmes32]]/$P$23 -> 0.13055841 | S22: =Table15[[#This Row],[Proj_2021_Total43]]/$P$23 -> 0.26473994 | T22: =Q22*$V$23 -> 115624.94 | U22: =R22*$V$23 -> 112502.89 | V22: =S22*$V$23 -> 228127.83 | W22: =T22/$V$23 -> 0.13418152 | X22: =U22/$V$23 -> 0.13055841 | Y22: =V22/$V$23 -> 0.26473994 | Z22: =W22*$AB$23 -> 121727.02 | AA22: =X22*$AB$23 -> 118440.21 | AB22: =Y22*$AB$23 -> 240167.23
J23: =J22+J21+J20 -> 822222 | N23: =[1]Sheet1!$D$30 -> 846044.34 | P23: =P22+P21+P20 -> 846044.34 | V23: 861705.4 | AB23: 907181.72
A24: TD0601 | B24: Kanem | C24: Kanem | D24: TD06 | E24: Kanem | F24: 95631 | G24: 100953 | H24: 111367 | I24: 117564 | J24: 228931 | K24: =Table15[[#This Row],[Proj2020_Hommes]]/$J$27 -> 0.22350823 | L24: =Table15[[#This Row],[Proj2020_Femmes]]/$J$27 -> 0.23594531 | M24: =Table15[[#This Row],[Proj_2020_Total]]/$J$27 -> 0.45945355 | N24: 114593.51 | O24: 120970.05 | P24: 235563.56 | Q24: =Table15[[#This Row],[Proj2021_Hommes22]]/$P$27 -> 0.22350823 | R24: =Table15[[#This Row],[Proj2021_Femmes32]]/$P$27 -> 0.23594531 | S24: =Table15[[#This Row],[Proj_2021_Total43]]/$P$27 -> 0.45945355 | T24: =Q24*$V$27 -> 116714.74 | U24: =R24*$V$27 -> 123209.32 | V24: =S24*$V$27 -> 239924.06 | W24: =T24/$V$27 -> 0.22350823 | X24: =U24/$V$27 -> 0.23594531 | Y24: =V24/$V$27 -> 0.45945355 | Z24: =W24*$AB$27 -> 122874.34 | AA24: =X24*$AB$27 -> 129711.66 | AB24: =Y24*$AB$27 -> 252586
A25: TD0602 | B25: Nord Kanem | C25: Nord Kanem | D25: TD06 | E25: Kanem | F25: 58578 | G25: 58165 | H25: 68216 | I25: 67737 | J25: 135953 | K25: =Table15[[#This Row],[Proj2020_Hommes]]/$J$27 -> 0.13690624 | L25: =Table15[[#This Row],[Proj2020_Femmes]]/$J$27 -> 0.13594491 | M25: =Table15[[#This Row],[Proj_2020_Total]]/$J$27 -> 0.27285116 | N25: 70192.345 | O25: 69699.468 | P25: 139891.81 | Q25: =Table15[[#This Row],[Proj2021_Hommes22]]/$P$27 -> 0.13690624 | R25: =Table15[[#This Row],[Proj2021_Femmes32]]/$P$27 -> 0.13594491 | S25: =Table15[[#This Row],[Proj_2021_Total43]]/$P$27 -> 0.27285116 | T25: =Q25*$V$27 -> 71491.671 | U25: =R25*$V$27 -> 70989.669 | V25: =S25*$V$27 -> 142481.34 | W25: =T25/$V$27 -> 0.13690624 | X25: =U25/$V$27 -> 0.13594491 | Y25: =V25/$V$27 -> 0.27285116 | Z25: =W25*$AB$27 -> 75264.628 | AA25: =X25*$AB$27 -> 74736.133 | AB25: =Y25*$AB$27 -> 150000.76
A26: TD0603 | B26: Wadi Bissam | C26: Wadi-Bissam | D26: TD06 | E26: Kanem | F26: 54777 | G26: 59760 | H26: 63791 | I26: 69593 | J26: 133384 | K26: =Table15[[#This Row],[Proj2020_Hommes]]/$J$27 -> 0.12802548 | L26: =Table15[[#This Row],[Proj2020_Femmes]]/$J$27 -> 0.13966982 | M26: =Table15[[#This Row],[Proj_2020_Total]]/$J$27 -> 0.2676953 | N26: 65639.145 | O26: 71609.24 | P26: 137248.38 | Q26: =Table15[[#This Row],[Proj2021_Hommes22]]/$P$27 -> 0.12802548 | R26: =Table15[[#This Row],[Proj2021_Femmes32]]/$P$27 -> 0.13966982 | S26: =Table15[[#This Row],[Proj_2021_Total43]]/$P$27 -> 0.2676953 | T26: =Q26*$V$27 -> 66854.186 | U26: =R26*$V$27 -> 72934.793 | V26: =S26*$V$27 -> 139788.98 | W26: =T26/$V$27 -> 0.12802548 | X26: =U26/$V$27 -> 0.13966982 | Y26: =V26/$V$27 -> 0.2676953 | Z26: =W26*$AB$27 -> 70382.401 | AA26: =X26*$AB$27 -> 76783.91 | AB26: =Y26*$AB$27 -> 147166.31
J27: =J26+J25+J24 -> 498268 | N27: =[1]Sheet1!$D$31 -> 512703.76 | P27: =P26+P25+P24 -> 512703.76 | V27: 522194.38 | AB27: 549753.07
A28: TD0701 | B28: Mamdi | C28: Mamdi | D28: TD07 | E28: Lac | F28: 79010 | G28: 74744 | H28: 85105 | I28: 80510 | J28: 165615 | K28: =Table15[[#This Row],[Proj2020_Hommes]]/$J$32 -> 0.13325536 | L28: =Table15[[#This Row],[Proj2020_Femmes]]/$J$32 -> 0.12606062 | M28: =Table15[[#This Row],[Proj_2020_Total]]/$J$32 -> 0.25931598 | N28: 87570.788 | O28: 82842.655 | P28: 170413.44 | Q28: =Table15[[#This Row],[Proj2021_Hommes22]]/$P$32 -> 0.13325536 | R28: =Table15[[#This Row],[Proj2021_Femmes32]]/$P$32 -> 0.12606062 | S28: =Table15[[#This Row],[Proj_2021_Total43]]/$P$32 -> 0.25931598 | T28: =Q28*$V$32 -> 89191.805 | U28: =R28*$V$32 -> 84376.149 | V28: =S28*$V$32 -> 173567.95 | W28: =T28/$V$32 -> 0.13325536 | X28: =U28/$V$32 -> 0.12606062 | Y28: =V28/$V$32 -> 0.25931598 | Z28: =W28*$AB$32 -> 93898.882 | AA28: =X28*$AB$32 -> 88829.082 | AB28: =Y28*$AB$32 -> 182727.96
A29: TD0702 | B29: Wayi | C29: Wayi | D29: TD07 | E29: Lac | F29: 134011 | G29: 136643 | H29: 153743 | I29: 156763 | J29: 310506 | K29: =Table15[[#This Row],[Proj2020_Hommes]]/$J$32 -> 0.24072708 | L29: =Table15[[#This Row],[Proj2020_Femmes]]/$J$32 -> 0.24545573 | M29: =Table15[[#This Row],[Proj_2020_Total]]/$J$32 -> 0.48618281 | N29: 158197.47 | O29: 161304.97 | P29: 319502.44 | Q29: =Table15[[#This Row],[Proj2021_Hommes22]]/$P$32 -> 0.24072708 | R29: =Table15[[#This Row],[Proj2021_Femmes32]]/$P$32 -> 0.24545573 | S29: =Table15[[#This Row],[Proj_2021_Total43]]/$P$32 -> 0.48618281 | T29: =Q29*$V$32 -> 161125.85 | U29: =R29*$V$32 -> 164290.87 | V29: =S29*$V$32 -> 325416.73 | W29: =T29/$V$32 -> 0.24072708 | X29: =U29/$V$32 -> 0.24545573 | Y29: =V29/$V$32 -> 0.48618281 | Z29: =W29*$AB$32 -> 169629.23 | AA29: =X29*$AB$32 -> 172961.29 | AB29: =Y29*$AB$32 -> 342590.52
A30: TD0703 | B30: Kaya | C30: Kaya | D30: TD07 | E30: Lac | F30: 27453 | G30: 26731 | H30: 29030 | I30: 28267 | J30: 57297 | K30: =Table15[[#This Row],[Proj2020_Hommes]]/$J$32 -> 0.045454474 | L30: =Table15[[#This Row],[Proj2020_Femmes]]/$J$32 -> 0.044259787 | M30: =Table15[[#This Row],[Proj_2020_Total]]/$J$32 -> 0.089714262 | N30: 29871.1 | O30: 29085.994 | P30: 58957.094 | Q30: =Table15[[#This Row],[Proj2021_Hommes22]]/$P$32 -> 0.045454474 | R30: =Table15[[#This Row],[Proj2021_Femmes32]]/$P$32 -> 0.044259787 | S30: =Table15[[#This Row],[Proj_2021_Total43]]/$P$32 -> 0.089714262 | T30: =Q30*$V$32 -> 30424.042 | U30: =R30*$V$32 -> 29624.402 | V30: =S30*$V$32 -> 60048.444 | W30: =T30/$V$32 -> 0.045454474 | X30: =U30/$V$32 -> 0.044259787 | Y30: =V30/$V$32 -> 0.089714262 | Z30: =W30*$AB$32 -> 32029.664 | AA30: =X30*$AB$32 -> 31187.823 | AB30: =Y30*$AB$32 -> 63217.487
A31: TD0704 | B31: Fouli | C31: Fouli | D31: TD07 | E31: Lac | F31: 40496 | G31: 37630 | H31: 54553 | I31: 50690 | J31: 105243 | K31: =Table15[[#This Row],[Proj2020_Hommes]]/$J$32 -> 0.085417772 | L31: =Table15[[#This Row],[Proj2020_Femmes]]/$J$32 -> 0.07936918 | M31: =Table15[[#This Row],[Proj_2020_Total]]/$J$32 -> 0.16478695 | N31: 56133.591 | O31: 52158.666 | P31: 108292.26 | Q31: =Table15[[#This Row],[Proj2021_Hommes22]]/$P$32 -> 0.085417772 | R31: =Table15[[#This Row],[Proj2021_Femmes32]]/$P$32 -> 0.07936918 | S31: =Table15[[#This Row],[Proj_2021_Total43]]/$P$32 -> 0.16478695 | T31: =Q31*$V$32 -> 57172.675 | U31: =R31*$V$32 -> 53124.171 | V31: =S31*$V$32 -> 110296.85 | W31: =T31/$V$32 -> 0.085417772 | X31: =U31/$V$32 -> 0.07936918 | Y31: =V31/$V$32 -> 0.16478695 | Z31: =W31*$AB$32 -> 60189.95 | AA31: =X31*$AB$32 -> 55927.787 | AB31: =Y31*$AB$32 -> 116117.74
J32: =J31+J30+J29+J28 -> 638661 | N32: =[1]Sheet1!$D$32 -> 657165.24 | P32: =P31+P30+P29+P28 -> 657165.24 | V32: 669329.97 | AB32: 704653.71
A33: TD0801 | B33: Lac Wey | C33: Lac Wey | D33: TD08 | E33: Logone Occidental | F33: 209328 | G33: 216109 | H33: 244417 | I33: 252334 | J33: 496751 | K33: =Table15[[#This Row],[Proj2020_Hommes]]/$J$37 -> 0.23671409 | L33: =Table15[[#This Row],[Proj2020_Femmes]]/$J$37 -> 0.24438158 | M33: =Table15[[#This Row],[Proj_2020_Total]]/$J$37 -> 0.48109567 | N33: 251498.46 | O33: 259644.84 | P33: 511143.3 | Q33: =Table15[[#This Row],[Proj2021_Hommes22]]/$P$37 -> 0.23671409 | R33: =Table15[[#This Row],[Proj2021_Femmes32]]/$P$37 -> 0.24438158 | S33: =Table15[[#This Row],[Proj_2021_Total43]]/$P$37 -> 0.48109567 | T33: =Q33*$V$37 -> 256153.93 | U33: =R33*$V$37 -> 264451.11 | V33: =S33*$V$37 -> 520605.04 | W33: =T33/$V$37 -> 0.23671409 | X33: =U33/$V$37 -> 0.24438158 | Y33: =V33/$V$37 -> 0.48109567 | Z33: =W33*$AB$37 -> 269672.4 | AA33: =X33*$AB$37 -> 278407.45 | AB33: =Y33*$AB$37 -> 548079.85
A34: TD0802 | B34: Dodjé | C34: Dodje | D34: TD08 | E34: Logone Occidental | F34: 65617 | G34: 70887 | H34: 76616 | I34: 82769 | J34: 159385 | K34: =Table15[[#This Row],[Proj2020_Hommes]]/$J$37 -> 0.074201412 | L34: =Table15[[#This Row],[Proj2020_Femmes]]/$J$37 -> 0.080160497 | M34: =Table15[[#This Row],[Proj_2020_Total]]/$J$37 -> 0.15436191 | N34: 78835.785 | O34: 85167.056 | P34: 164002.84 | Q34: =Table15[[#This Row],[Proj2021_Hommes22]]/$P$37 -> 0.074201412 | R34: =Table15[[#This Row],[Proj2021_Femmes32]]/$P$37 -> 0.080160497 | S34: =Table15[[#This Row],[Proj_2021_Total43]]/$P$37 -> 0.15436191 | T34: =Q34*$V$37 -> 80295.109 | U34: =R34*$V$37 -> 86743.576 | V34: =S34*$V$37 -> 167038.69 | W34: =T34/$V$37 -> 0.074201412 | X34: =U34/$V$37 -> 0.080160497 | Y34: =V34/$V$37 -> 0.15436191 | Z34: =W34*$AB$37 -> 84532.665 | AA34: =X34*$AB$37 -> 91321.449 | AB34: =Y34*$AB$37 -> 175854.11
A35: TD0803 | B35: Guéni | C35: Gueni | D35: TD08 | E35: Logone Occidental | F35: 56819 | G35: 61270 | H35: 66344 | I35: 71540 | J35: 137884 | K35: =Table15[[#This Row],[Proj2020_Hommes]]/$J$37 -> 0.064253139 | L35: =Table15[[#This Row],[Proj2020_Femmes]]/$J$37 -> 0.069285384 | M35: =Table15[[#This Row],[Proj_2020_Total]]/$J$37 -> 0.13353852 | N35: 68266.176 | O35: 73612.719 | P35: 141878.9 | Q35: =Table15[[#This Row],[Proj2021_Hommes22]]/$P$37 -> 0.064253139 | R35: =Table15[[#This Row],[Proj2021_Femmes32]]/$P$37 -> 0.069285384 | S35: =Table15[[#This Row],[Proj_2021_Total43]]/$P$37 -> 0.13353852 | T35: =Q35*$V$37 -> 69529.846 | U35: =R35*$V$37 -> 74975.359 | V35: =S35*$V$37 -> 144505.2 | W35: =T35/$V$37 -> 0.064253139 | X35: =U35/$V$37 -> 0.069285384 | Y35: =V35/$V$37 -> 0.13353852 | Z35: =W35*$AB$37 -> 73199.268 | AA35: =X35*$AB$37 -> 78932.167 | AB35: =Y35*$AB$37 -> 152131.43
A36: TD0804 | B36: Ngourkosso | C36: Ngourkosso | D36: TD08 | E36: Logone Occidental | F36: 97345 | G36: 106934 | H36: 113662 | I36: 124859 | J36: 238521 | K36: =Table15[[#This Row],[Proj2020_Hommes]]/$J$37 -> 0.11007989 | L36: =Table15[[#This Row],[Proj2020_Femmes]]/$J$37 -> 0.12092401 | M36: =Table15[[#This Row],[Proj_2020_Total]]/$J$37 -> 0.2310039 | N36: 116955.11 | O36: 128476.52 | P36: 245431.64 | Q36: =Table15[[#This Row],[Proj2021_Hommes22]]/$P$37 -> 0.11007989 | R36: =Table15[[#This Row],[Proj2021_Femmes32]]/$P$37 -> 0.12092401 | S36: =Table15[[#This Row],[Proj_2021_Total43]]/$P$37 -> 0.2310039 | T36: =Q36*$V$37 -> 119120.06 | U36: =R36*$V$37 -> 130854.74 | V36: =S36*$V$37 -> 249974.8 | W36: =T36/$V$37 -> 0.11007989 | X36: =U36/$V$37 -> 0.12092401 | Y36: =V36/$V$37 -> 0.2310039 | Z36: =W36*$AB$37 -> 125406.6 | AA36: =X36*$AB$37 -> 137760.57 | AB36: =Y36*$AB$37 -> 263167.17
J37: =J36+J35+J34+J33 -> 1032541 | N37: =[1]Sheet1!$D$33 -> 1062456.7 | P37: =P36+P35+P34+P33 -> 1062456.7 | V37: 1082123.7 | AB37: 1139232.6
A38: TD0901 | B38: La Pendé | C38: La Pende | D38: TD09 | E38: Logone Oriental | F38: 99688 | G38: 106239 | H38: 115731 | I38: 123336 | J38: 239067 | K38: =Table15[[#This Row],[Proj2020_Hommes]]/$J$44 -> 0.099669122 | L38: =Table15[[#This Row],[Proj2020_Femmes]]/$J$44 -> 0.10621865 | M38: =Table15[[#This Row],[Proj_2020_Total]]/$J$44 -> 0.20588777 | N38: 119084.05 | O38: 126909.38 | P38: 245993.43 | Q38: =Table15[[#This Row],[Proj2021_Hommes22]]/$P$44 -> 0.099669122 | R38: =Table15[[#This Row],[Proj2021_Femmes32]]/$P$44 -> 0.10621865 | S38: =Table15[[#This Row],[Proj_2021_Total43]]/$P$44 -> 0.20588777 | T38: =Q38*$V$44 -> 121288.4 | U38: =R38*$V$44 -> 129258.59 | V38: =S38*$V$44 -> 250547 | W38: =T38/$V$44 -> 0.099669122 | X38: =U38/$V$44 -> 0.10621865 | Y38: =V38/$V$44 -> 0.20588777 | Z38: =W38*$AB$44 -> 127689.37 | AA38: =X38*$AB$44 -> 136080.19 | AB38: =Y38*$AB$44 -> 263769.56
A39: TD0902 | B39: Kouh Est | C39: Kouh Est | D39: TD09 | E39: Logone Oriental | F39: 62349 | G39: 67722 | H39: 72383 | I39: 78620 | J39: 151003 | K39: =Table15[[#This Row],[Proj2020_Hommes]]/$J$44 -> 0.062337231 | L39: =Table15[[#This Row],[Proj2020_Femmes]]/$J$44 -> 0.06770862 | M39: =Table15[[#This Row],[Proj_2020_Total]]/$J$44 -> 0.13004585 | N39: 74480.135 | O39: 80897.838 | P39: 155377.97 | Q39: =Table15[[#This Row],[Proj2021_Hommes22]]/$P$44 -> 0.062337231 | R39: =Table15[[#This Row],[Proj2021_Femmes32]]/$P$44 -> 0.06770862 | S39: =Table15[[#This Row],[Proj_2021_Total43]]/$P$44 -> 0.13004585 | T39: =Q39*$V$44 -> 75858.831 | U39: =R39*$V$44 -> 82395.332 | V39: =S39*$V$44 -> 158254.16 | W39: =T39/$V$44 -> 0.062337231 | X39: =U39/$V$44 -> 0.06770862 | Y39: =V39/$V$44 -> 0.13004585 | Z39: =W39*$AB$44 -> 79862.264 | AA39: =X39*$AB$44 -> 86743.728 | AB39: =Y39*$AB$44 -> 166605.99
A40: TD0903 | B40: Kouh Ouest | C40: Kouh Ouest | D40: TD09 | E40: Logone Oriental | F40: 31240 | G40: 32307 | H40: 36268 | I40: 37505 | J40: 73773 | K40: =Table15[[#This Row],[Proj2020_Hommes]]/$J$44 -> 0.031234498 | L40: =Table15[[#This Row],[Proj2020_Femmes]]/$J$44 -> 0.032299819 | M40: =Table15[[#This Row],[Proj_2020_Total]]/$J$44 -> 0.063534318 | N40: 37318.784 | O40: 38591.623 | P40: 75910.407 | Q40: =Table15[[#This Row],[Proj2021_Hommes22]]/$P$44 -> 0.031234498 | R40: =Table15[[#This Row],[Proj2021_Femmes32]]/$P$44 -> 0.032299819 | S40: =Table15[[#This Row],[Proj_2021_Total43]]/$P$44 -> 0.063534318 | T40: =Q40*$V$44 -> 38009.589 | U40: =R40*$V$44 -> 39305.99 | V40: =S40*$V$44 -> 77315.579 | W40: =T40/$V$44 -> 0.031234498 | X40: =U40/$V$44 -> 0.032299819 | Y40: =V40/$V$44 -> 0.063534318 | Z40: =W40*$AB$44 -> 40015.537 | AA40: =X40*$AB$44 -> 41380.355 | AB40: =Y40*$AB$44 -> 81395.892
...

Sheet ProjPop21_22_23_admin2
H1: Population 2021 | K1: Population 2022 | N1: Population 2023
A2: admin2Pcode | B2: admin2Name_fr | C2: admin2RefName | D2: admin1Pcode | E2: admin1Name_fr | F2: Proj2016_Hommes | G2: Proj2016_Femmes | H2: Proj2021_Hommes22 | I2: Proj2021_Femmes32 | J2: Proj_2021_Total43 | K2: Proj2022_Hommes | L2: Proj2022_Femmes | M2: Proj_2022_Total | N2: Proj2022_Hommes | O2: Proj2022_Femmes | P2: Proj_2022_Total
A3: TD0101 | B3: Batha Ouest | C3: Batha Ouest | D3: TD01 | E3: Batha | F3: 125463 | G3: 128277 | H3: 154132.29 | I3: 145248.64 | J3: 287312.61 | K3: 144693.71 | L3: 147937.33 | M3: 292631.04 | N3: =ProjPop20_21_22_23admin2!AA2 -> 152329.89 | O3: =ProjPop20_21_22_23admin2!AB2 -> 155744.69 | P3: =ProjPop20_21_22_23admin2!AC2 -> 308074.57
A4: TD0102 | B4: Batha Est | C4: Batha Est | D4: TD01 | E4: Batha | F4: 107365 | G4: 124085 | H4: 131896.17 | I4: 140503.02 | J4: 262071.93 | K4: 123819.26 | L4: 143103.86 | M4: 266923.13 | N4: =ProjPop20_21_22_23admin2!AA3 -> 130353.8 | O4: =ProjPop20_21_22_23admin2!AB3 -> 150656.14 | P4: =ProjPop20_21_22_23admin2!AC3 -> 281009.94
A5: TD0103 | B5: Fitri | C5: Fitri | D5: TD01 | E5: Batha | F5: 69296 | G5: 72394 | H5: 85130.895 | I5: 81970.986 | J5: 160436.27 | K5: 79917.744 | L5: 83488.345 | M5: 163406.09 | N5: =ProjPop20_21_22_23admin2!AA4 -> 84135.385 | O5: =ProjPop20_21_22_23admin2!AB4 -> 87894.424 | P5: =ProjPop20_21_22_23admin2!AC4 -> 172029.81
A6: TD0201 | B6: Borkou | C6: Borkou | D6: TD02 | E6: Borkou | F6: 47162 | G6: 40583 | H6: 55800.116 | I6: 48016.973 | J6: 103817.09 | K6: 56833.027 | L6: 48905.811 | M6: 105738.84 | N6: =ProjPop20_21_22_23admin2!AA5 -> 59832.378 | O6: =ProjPop20_21_22_23admin2!AB5 -> 51486.804 | P6: =ProjPop20_21_22_23admin2!AC5 -> 111319.18
A7: TD0202 | B7: Borkou Yala | C7: Borkou Yala | D7: TD02 | E7: Borkou | F7: 16988 | G7: 15371 | H7: 20099.937 | I7: 18187.078 | J7: 38287.014 | K7: 20472.005 | L7: 18523.738 | M7: 38995.743 | N7: =ProjPop20_21_22_23admin2!AA6 -> 21552.411 | O7: =ProjPop20_21_22_23admin2!AB6 -> 19501.324 | P7: =ProjPop20_21_22_23admin2!AC6 -> 41053.734
A8: TD0301 | B8: Baguirmi | C8: Baguirmi | D8: TD03 | E8: Chari-Baguirmi | F8: 135091 | G8: 134062 | H8: 158244.56 | I8: 157038.6 | J8: 315283.16 | K8: 161173.81 | L8: 159945.53 | M8: 321119.34 | N8: =ProjPop20_21_22_23admin2!AA7 -> 169679.72 | O8: =ProjPop20_21_22_23admin2!AB7 -> 168386.62 | P8: =ProjPop20_21_22_23admin2!AC7 -> 338066.34
A9: TD0302 | B9: Chari | C9: Chari | D9: TD03 | E9: Chari-Baguirmi | F9: 115724 | G9: 119011 | H9: 135557.78 | I9: 139408.2 | J9: 274965.98 | K9: 138067.08 | L9: 141988.77 | M9: 280055.85 | N9: =ProjPop20_21_22_23admin2!AA8 -> 145353.54 | O9: =ProjPop20_21_22_23admin2!AB8 -> 149482.2 | P9: =ProjPop20_21_22_23admin2!AC8 -> 294835.74
A10: TD0303 | B10: Loug-Chari | C10: Loug-Chari | D10: TD03 | E10: Chari-Baguirmi | F10: 117519 | G10: 120935 | H10: 137661 | I10: 141661.64 | J10: 279322.65 | K10: 140209.23 | L10: 144283.93 | M10: 284493.17 | N10: =ProjPop20_21_22_23admin2!AA9 -> 147608.75 | O10: =ProjPop20_21_22_23admin2!AB9 -> 151898.49 | P10: =ProjPop20_21_22_23admin2!AC9 -> 299507.23
A11: TD0401 | B11: Guéra | C11: Guera | D11: TD04 | E11: Guera | F11: 108267 | G11: 113049 | H11: 102518.53 | I11: 107048.06 | J11: 209566.59 | K11: 104416.24 | L11: 109029.62 | M11: 213445.86 | N11: =ProjPop20_21_22_23admin2!AA10 -> 109926.78 | O11: =ProjPop20_21_22_23admin2!AB10 -> 114783.63 | P11: =ProjPop20_21_22_23admin2!AC10 -> 224710.41
A12: TD0402 | B12: Abtouyour | C12: Abtouyour | D12: TD04 | E12: Guera | F12: 104673 | G12: 110208 | H12: 99115.716 | I12: 104358.33 | J12: 203474.04 | K12: 100950.44 | L12: 106290.1 | M12: 207240.54 | N12: =ProjPop20_21_22_23admin2!AA11 -> 106278.08 | O12: =ProjPop20_21_22_23admin2!AB11 -> 111899.53 | P12: =ProjPop20_21_22_23admin2!AC11 -> 218177.61
A13: TD0403 | B13: Barh-Signaka | C13: Barh-Signaka | D13: TD04 | E13: Guera | F13: 65394 | G13: 67528 | H13: 61923.527 | I13: 63942.37 | J13: 125865.9 | K13: 63069.789 | L13: 65126.003 | M13: 128195.79 | N13: =ProjPop20_21_22_23admin2!AA12 -> 66398.283 | O13: =ProjPop20_21_22_23admin2!AB12 -> 68563.013 | P13: =ProjPop20_21_22_23admin2!AC12 -> 134961.3
A14: TD0404 | B14: Mangalmé | C14: Mangalme | D14: TD04 | E14: Guera | F14: 56874 | G14: 64928 | H14: 53855.359 | I14: 61481.069 | J14: 115336.43 | K14: 54852.271 | L14: 62619.141 | M14: 117471.41 | N14: =ProjPop20_21_22_23admin2!AA13 -> 57747.088 | O14: =ProjPop20_21_22_23admin2!AB13 -> 65923.852 | P14: =ProjPop20_21_22_23admin2!AC13 -> 123670.94
... A72: TD2303 | B72: Mourtcha | C72: Mourtcha | D72: TD23 | E72: Ennedi Ouest | F72: 15044 | G72: 12309 | H72: 17691.113 | I72: 14474.547 | J72: 32165.661 | K72: 18018.592 | L72: 14742.485 | M72: 32761.077 | N72: =ProjPop20_21_22_23admin2!AA71 -> 18969.519 | O72: =ProjPop20_21_22_23admin2!AB71 -> 15520.516 | P72: =ProjPop20_21_22_23admin2!AC71 -> 34490.035

Sheet ProjPop20_21_22_23_admin1
A1: admin1Pcode | B1: admin1Name_fr | C1: admin1RefName | D1: Proj2016 | E1: Proj2017 | F1: Proj2018 | G1: Proj2019 | H1: Proj2020 | I1: Proj 2021 | J1: Proj 2022 | K1: Proj 2023
A2: TD19 | B2: Barh-El-Gazel | C2: Barh-El-Gazel | D2: 330173 | E2: 337694 | F2: 349221 | G2: 361143 | H2: 373443 | I2: 384262.34 | J2: 722960.25 | K2: 412030.14 | L2: Barh El Gazal
A3: TD01 | B3: Batha | C3: Batha | D3: 626881 | E3: 626592 | F3: 646664 | G3: 667646 | H3: 689835 | I3: 709820.81 | J3: 144734.58 | K3: 761114.32 | L3: Batha
A4: TD02 | B4: Borkou | C4: Borkou | D4: 120104 | E4: 125005 | F4: 129275 | G4: 133644 | H4: 138103 | I4: 142104.1 | J4: 885668.36 | K4: 152372.92 | L4: Borkou
A5: TD03 | B5: Chari-Baguirmi | C5: Chari-Baguirmi | D5: 742342 | E5: 762056 | F5: 788626 | G5: 816270 | H5: 845088 | I5: 869571.78 | J5: 666353.6 | K5: 932409.31 | L5: Chari Baguirmi
A6: TD20 | B6: Ennedi Est | C6: Ennedi Est | D6: 137709 | E6: 143078 | F6: 147956 | G6: 152922 | H6: 158099 | I6: 162679.42 | J6: 861705.4 | K6: 174435.06 | L6: Ennedi Est
A7: TD23 | B7: Ennedi Ouest | C7: Ennedi Ouest | D7: 77795 | E7: 80828 | F7: 83584 | G7: 86388 | H7: 89313 | I7: 91900.565 | J7: 522194.38 | K7: 98541.54 | L7: Ennedi Ouest
A8: TD04 | B8: Guéra | C8: Guera | D8: 690921 | E8: 600448 | F8: 610900 | G8: 622190 | H8: 635822 | I8: 654242.96 | J8: 669329.97 | K8: 701520.26 | L8: Guéra
A9: TD05 | B9: Hadjer-Lamis | C9: Hadjer-Lamis | D9: 727497 | E9: 742989 | F9: 768212 | G9: 794345 | H9: 822223 | I9: 846044.34 | J9: 1082123.7 | K9: 907181.72 | L9: Hadjer Lamis
A10: TD06 | B10: Kanem | C10: Kanem | D10: 427864 | E10: 448332 | F10: 464480 | G10: 481131 | H10: 498268 | I10: 512703.76 | J10: 1216910.5 | K10: 549753.07 | L10: Kanem
A11: TD07 | B11: Lac | C11: Lac | D11: 556720 | E11: 575876 | F11: 596068 | G11: 616984 | H11: 638662 | I11: 657165.24 | J11: 972880.32 | K11: 704653.71 | L11: Lac
A12: TD08 | B12: Logone Occidental | C12: Logone Occidental | D12: 884310 | E12: 927752 | F12: 961503 | G12: 996384 | H12: 1032542 | I12: 1062456.7 | J12: 1201741.5 | K12: 1139232.6 | L12: Logone Occidental
A13: TD09 | B13: Logone Oriental | C13: Logone Oriental | D13: 1000192 | E13: 1045090 | F13: 1082404 | G13: 1121022 | H13: 1161153 | I13: 1194793.8 | J13: 885983.81 | K13: 1281132.7 | L13: Logone Oriental
A14: TD10 | B14: Mandoul | C14: Mandoul | D14: 806050 | E14: 838080 | F14: 867102 | G14: 897129 | H14: 928304 | I14: 955198.71 | J14: 919928.11 | K14: 1024223.9 | L14: Mandoul
A15: TD11 | B15: Mayo-Kebbi Est | C15: Mayo-Kebbi Est | D15: 994344 | E15: 1030686 | F15: 1067875 | G15: 1106515 | H15: 1146679 | I15: 1179900.4 | J15: 1120274.8 | K15: 1265163.1 | L15: Mayo Kebbi Est | N15: 2020 | O15: Structure 2020 | P15: Pop 2021 | Q15: Pop 2022 | R15: Struct 2022 | S15: Pop 2023
A16: TD12 | B16: Mayo-Kebbi Ouest | C16: Mayo-Kebbi Ouest | D16: 724432 | E16: 757831 | F16: 785944 | G16: 815107 | H16: 845389 | I16: 869881.5 | J16: 472137.84 | K16: 932741.41 | L16: Mayo Kebbi Ouest | M16: Ennedi Est | N16: 158099 | O16: =N16/$N$18 -> 0.63901104 | P16: =O16*$P$19 -> 162679.42 | Q16: 165690.77 | R16: =Q16/$Q$18 -> 0.63901104 | S16: =R16*$S$19 -> 174435.06
A17: TD13 | B17: Moyen-Chari | C17: Moyen-Chari | D17: 754641 | E17: 789918 | F17: 818259 | G17: 847520 | H17: 877778 | I17: 903208.87 | J17: 1044039.8 | K17: 968477.11 | L17: Moyen Chari | M17: Ennedi Ouest | N17: 89313 | O17: =N17/$N$18 -> 0.36098896 | P17: =O17*$P$19 -> 91900.565 | Q17: 93601.729 | R17: =Q17/$Q$18 -> 0.36098896 | S17: =R17*$S$19 -> 98541.54
A18: TD18 | B18: N'Djamena | C18: NDjamena | D18: 1221036 | E18: 1390309 | F18: 1454671 | G18: 1521882 | H18: 1592258 | I18: 1638388.7 | J18: 790981.93 | K18: 1756782.9 | L18: N’Djaména | N18: =SUM(N16:N17) -> 247412 | P18: =SUM(P16:P17) -> 254579.99 | Q18: =SUM(Q16:Q17) -> 259292.5
A19: TD14 | B19: Ouaddaï | C19: Ouaddai | D19: 925533 | E19: 963234 | F19: 997257 | G19: 1032467 | H19: 1068945 | I19: 1099914.3 | J19: 1668716.8 | K19: 1179397 | L19: Ouaddaï | P19: 254579.99 | S19: 272976.6
A20: TD15 | B20: Salamat | C20: Salamat | D20: 387969 | E20: 405292 | F20: 419846 | G20: 434903 | H20: 450505 | I20: 463556.97 | J20: 391375.39 | K20: 497054.81 | L20: Salamat
A21: TD21 | B21: Sila | C21: Sila | D21: 497261 | E21: 509070 | F21: 526290 | G21: 544183 | H21: 563716 | I21: 580047.91 | J21: 165690.77 | K21: 621963.69 | L21: Sila
A22: TD16 | B22: Tandjilé | C22: Tandjile | D22: 849481 | E22: 893837 | F22: 926792 | G22: 960885 | H22: 996203 | I22: 1025064.9 | J22: 93601.729 | K22: 1099138.7 | L22: Tandjilé
A23: TD22 | B23: Tibesti | C23: Tibesti | D23: 32704 | E23: 34131 | F23: 35326 | G23: 36545 | H23: 37784 | I23: 38878.673 | J23: 590785.13 | K23: 41688.148 | L23: Tibesti
A24: TD17 | B24: Wadi Fira | C24: Wadi Fira | D24: 652451 | E24: 678089 | F24: 702676 | G24: 728223 | H24: 754740 | I24: 776606.23 | J24: 39598.353 | K24: 832725.83 | L24: Wadi Fira
A25: TD | D25: 14168410 | E25: 14706217 | F25: 15230931 | G25: 15775428 | H25: 16344852 | I25: =SUM(I2:I24) -> 16818393 | J25: =SUM(J2:J24) -> 17129717
I27: 16818393

Sheet ProjPop2020_admin1_GroupesAge
E1: G R O U P E S D ' A G E S
A2: admin1Pcode | B2: admin1Name_fr | C2: admin1RefName | D2: Sexe | E2: 0-4 | F2: 5-9 | G2: 10-14 | H2: 15-19 | I2: 20-24 | J2: 25-29 | K2: 30-34 | L2: 35-39 | M2: 40-44 | N2: 45-49 | O2: 50-54 | P2: 55-59 | Q2: 60-64 | R2: 65-69 | S2: 70-74 | T2: 75-79 | U2: 80+ | V2: Total | W2: 0-42 | X2: 5-93 | Y2: 10-14 4 | Z2: 15-19 5 | AA2: 20-24 6 | AB2: 25-29 7 | AC2: 30-34 8 | AD2: 35-39 9 | AE2: 40-44 10 | AF2: 45-49 11 | AG2: 50-54 12 | AH2: 55-59 13 | AI2: 60-64 14 | AJ2: 65-69 15 | AK2: 70-74 16 | AL2: 75-79 17 | AM2: 80+ 18 | AN2: Total19
A3: TD01 | B3: Batha | C3: Batha | D3: Femmes | E3: 62595 | F3: 51417 | G3: 59533 | H3: 44850 | I3: 27264 | J3: 20064 | K3: 18803 | L3: 16410 | M3: 13177 | N3: 10619 | O3: 8148 | P3: 6116 | Q3: 4238 | R3: 2989 | S3: 2234 | T3: 1487 | U3: 1516 | V3: =SUM(E3:U3) -> 351460
A4: TD01 | B4: Batha | C4: Batha | D4: Hommes | E4: 65394 | F4: 53631 | G4: 60960 | H4: 45487 | I4: 26913 | J4: 17988 | K4: 11992 | L4: 9300 | M4: 9782 | N4: 9151 | O4: 7758 | P4: 6300 | Q4: 4492 | R4: 3301 | S4: 2562 | T4: 1715 | U4: 1652 | V4: =SUM(E4:U4) -> 338378
A5: TD01 | B5: Batha | C5: Batha | D5: Total | E5: 127989 | F5: 105049 | G5: 120493 | H5: 90336 | I5: 54176 | J5: 38052 | K5: 30795 | L5: 25710 | M5: 22959 | N5: 19770 | O5: 15906 | P5: 12416 | Q5: 8730 | R5: 6290 | S5: 4795 | T5: 3202 | U5: 3167 | V5: =SUM(E5:U5) -> 689835
A6: TD02 | B6: Borkou | C6: Borkou | D6: Femmes | E6: 13121 | F6: 11116 | G6: 6700 | H6: 6454 | I6: 5599 | J6: 4623 | K6: 3980 | L6: 3396 | M6: 2888 | N6: 2404 | O6: 1886 | P6: 1409 | Q6: 907 | R6: 585 | S6: 392 | T6: 236 | U6: 174 | V6: =SUM(E6:U6) -> 65870
A7: TD02 | B7: Borkou | C7: Borkou | D7: Hommes | E7: 13708 | F7: 11594 | G7: 8218 | H7: 7901 | I7: 6601 | J7: 5235 | K7: 4105 | L7: 3268 | M7: 2443 | N7: 2024 | O7: 2052 | P7: 1777 | Q7: 1215 | R7: 847 | S7: 613 | T7: 377 | U7: 256 | V7: =SUM(E7:U7) -> 72234
A8: TD02 | B8: Borkou | C8: Borkou | D8: Total | E8: 26829 | F8: 22710 | G8: 14918 | H8: 14355 | I8: 12200 | J8: 9858 | K8: 8085 | L8: 6663 | M8: 5331 | N8: 4427 | O8: 3938 | P8: 3185 | Q8: 2122 | R8: 1432 | S8: 1005 | T8: 613 | U8: 430 | V8: =SUM(E8:U8) -> 138101
A9: TD03 | B9: Chari-Baguirmi | C9: Chari-Baguirmi | D9: Femmes | E9: 81345 | F9: 66054 | G9: 56716 | H9: 50458 | I9: 36301 | J9: 27528 | K9: 24480 | L9: 20673 | M9: 16077 | N9: 12693 | O9: 9723 | P9: 7301 | Q9: 5195 | R9: 3646 | S9: 2516 | T9: 1569 | U9: 1384 | V9: =SUM(E9:U9) -> 423659
A10: TD03 | B10: Chari-Baguirmi | C10: Chari-Baguirmi | D10: Hommes | E10: 84983 | F10: 68898 | G10: 57799 | H10: 51109 | I10: 35812 | J10: 25488 | K10: 18746 | L10: 14939 | M10: 13611 | N10: 12038 | O10: 10279 | P10: 8497 | Q10: 6600 | R10: 4976 | S10: 3479 | T10: 2195 | U10: 1981 | V10: =SUM(E10:U10) -> 421430
A11: TD03 | B11: Chari-Baguirmi | C11: Chari-Baguirmi | D11: Total | E11: 166328 | F11: 134952 | G11: 114515 | H11: 101566 | I11: 72113 | J11: 53017 | K11: 43226 | L11: 35612 | M11: 29688 | N11: 24731 | O11: 20002 | P11: 15798 | Q11: 11795 | R11: 8622 | S11: 5995 | T11: 3764 | U11: 3365 | V11: =SUM(E11:U11) -> 845089
A12: TD04 | B12: Guéra | C12: Guera | D12: Femmes | E12: 38027 | F12: 32578 | G12: 124851 | H12: 47343 | I12: 13305 | J12: 13812 | K12: 11580 | L12: 9877 | M12: 8403 | N12: 6991 | O12: 5486 | P12: 4098 | Q12: 2640 | R12: 1701 | S12: 1138 | T12: 686 | U12: 1812 | V12: =SUM(E12:U12) -> 324328
A13: TD04 | B13: Guéra | C13: Guera | D13: Hommes | E13: 39728 | F13: 33981 | G13: 114145 | H13: 45421 | I13: 14390 | J13: 13796 | K13: 10571 | L13: 8414 | M13: 6292 | N13: 5210 | O13: 5284 | P13: 4574 | Q13: 3127 | R13: 2181 | S13: 1580 | T13: 972 | U13: 1827 | V13: =SUM(E13:U13) -> 311493
A14: TD04 | B14: Guéra | C14: Guera | D14: Total | E14: 77755 | F14: 66559 | G14: 238996 | H14: 92764 | I14: 27695 | J14: 27609 | K14: 22151 | L14: 18291 | M14: 14694 | N14: 12200 | O14: 10771 | P14: 8673 | Q14: 5767 | R14: 3882 | S14: 2718 | T14: 1658 | U14: 3639 | V14: =SUM(E14:U14) -> 635822
... A30: TD10 | B30: Mandoul | C30: Mandoul | D30: Femmes | E30: 87831 | F30: 73581 | G30: 63019 | H30: 55465 | I30: 37409 | J30: 27649 | K30: 27218 | L30: 24223 | M30: 19365 | N30: 15510 | O30: 11632 | P30: 8642 | Q30: 6258 | R30: 4401 | S30: 2975 | T30: 1787 | U30: 1270 | V30: =SUM(E30:U30) -> 468235
A31: TD10 | B31: Mandoul | C31: Mandoul | D31: Hommes | E31: 91759 | F31: 76 750 | G31: 64061 | H31: 57058 | I31: 40761 | J31: 29316 | K31: 21640 | L31: 17079 | M31: 15164 | N31: 12968 | O31: 10462 | P31: 8168 | Q31: 5904 | R31: 4087 | S31: 2434 | T31: 1356 | U31: 1105 | V31: =SUM(E31:U31) -> 383322
A32: TD10 | B32: Mandoul | C32: Mandoul | D32: Total | E32: 179589 | F32: 150331 | G32: 127080 | H32: 112523 | I32: 78169 | J32: 56966 | K32: 48858 | L32: 41302 | M32: 34529 | N32: 28479 | O32: 22093 | P32: 16810 | Q32: 12162 | R32: 8488 | S32: 5409 | T32: 3143 | U32: 2375 | V32: =SUM(E32:U32) -> 928306
A33: TD11 | B33: Mayo-Kebbi Est | C33: Mayo-Kebbi Est | D33: Femmes | E33: 113082 | F33: 91270 | G33: 73403 | H33: 66940 | I33: 51196 | J33: 39743 | K33: 33532 | L33: 27680 | M33: 21651 | N33: 17360 | O33: 13794 | P33: 10861 | Q33: 8502 | R33: 6378 | S33: 4487 | T33: 2819 | U33: 2242 | V33: =SUM(E33:U33) -> 584940
A34: TD11 | B34: Mayo-Kebbi Est | C34: Mayo-Kebbi Est | D34: Hommes | E34: 118139 | F34: 95200 | G34: 73672 | H34: 66353 | I34: 50232 | J34: 37297 | K34: 26730 | L34: 20339 | M34: 16822 | N34: 14020 | O34: 11708 | P34: 9531 | Q34: 7363 | R34: 5541 | S34: 3802 | T34: 2461 | U34: 2529 | V34: =SUM(E34:U34) -> 561739
A35: TD11 | B35: Mayo-Kebbi Est | C35: Mayo-Kebbi Est | D35: Total | E35: 231222 | F35: 186470 | G35: 147075 | H35: 133293 | I35: 101428 | J35: 77040 | K35: 60262 | L35: 48019 | M35: 38472 | N35: 31380 | O35: 25502 | P35: 20392 | Q35: 15864 | R35: 11918 | S35: 8289 | T35: 5281 | U35: 4772 | V35: =SUM(E35:U35) -> 1146679
A36: TD12 | B36: Mayo-Kebbi Ouest | C36: Mayo-Kebbi Ouest | D36: Femmes | E36: 84203 | F36: 67833 | G36: 55242 | H36: 49151 | I36: 37641 | J36: 29655 | K36: 25715 | L36: 21135 | M36: 15319 | N36: 11614 | O36: 9106 | P36: 6962 | Q36: 5048 | R36: 3620 | S36: 2556 | T36: 1637 | U36: 1497 | V36: =SUM(E36:U36) -> 427934
A37: TD12 | B37: Mayo-Kebbi Ouest | C37: Mayo-Kebbi Ouest | D37: Hommes | E37: 87969 | F37: 70755 | G37: 54988 | H37: 48347 | I37: 37704 | J37: 28953 | K37: 21036 | L37: 15970 | M37: 12567 | N37: 10150 | O37: 8529 | P37: 6833 | Q37: 4971 | R37: 3544 | S37: 2285 | T37: 1408 | U37: 1445 | V37: =SUM(E37:U37) -> 417454
A38: TD12 | B38: Mayo-Kebbi Ouest | C38: Mayo-Kebbi Ouest | D38: Total | E38: 172172 | F38: 138588 | G38: 110230 | H38: 97498 | I38: 75345 | J38: 58609 | K38: 46751 | L38: 37105 | M38: 27886 | N38: 21764 | O38: 17635 | P38: 13795 | Q38: 10019 | R38: 7164 | S38: 4841 | T38: 3045 | U38: 2943 | V38: =SUM(E38:U38) -> 845390
A39: TD13 | B39: Moyen-Chari | C39: Moyen-Chari | D39: Femmes | E39: 85236 | F39: 70391 | G39: 55759 | H39: 49183 | I39: 37093 | J39: 29175 | K39: 26022 | L39: 22096 | M39: 17484 | N39: 13831 | O39: 10246 | P39: 7497 | Q39: 5266 | R39: 3635 | S39: 2474 | T39: 1506 | U39: 1162 | V39: =SUM(E39:U39) -> 438056
A40: TD13 | B40: Moyen-Chari | C40: Moyen-Chari | D40: Hommes | E40: 89048 | F40: 73423 | G40: 57172 | H40: 50599 | I40: 38339 | J40: 29070 | K40: 22116 | L40: 17615 | M40: 14723 | N40: 12440 | O40: 10821 | P40: 8757 | Q40: 6192 | R40: 4246 | S40: 2583 | T40: 1447 | U40: 1131 | V40: =SUM(E40:U40) -> 439722
A41: TD13 | B41: Moyen-Chari | C41: Moyen-Chari | D41: Total | E41: 174285 | F41: 143813 | G41: 112931 | H41: 99782 | I41: 75432 | J41: 58245 | K41: 48138 | L41: 39711 | M41: 32207 | N41: 26271 | O41: 21067 | P41: 16254 | Q41: 11458 | R41: 7881 | S41: 5057 | T41: 2952 | U41: 2293 | V41: =SUM(E41:U41) -> 877777
A42: TD14 | B42: Ouaddaï | C42: Ouaddai | D42: Femmes | E42: 104055 | F42: 86783 | G42: 68080 | H42: 62018 | I42: 44788 | J42: 34033 | K42: 31932 | L42: 27888 | M42: 22542 | N42: 18037 | O42: 13307 | P42: 9644 | Q42: 6350 | R42: 4375 | S42: 3479 | T42: 2389 | U42: 2368 | V42: =SUM(E42:U42) -> 542068
A43: TD14 | B43: Ouaddaï | C43: Ouaddai | D43: Hommes | E43: 108708 | F43: 90521 | G43: 69501 | H43: 63537 | I43: 45913 | J43: 32448 | K43: 22527 | L43: 17521 | M43: 16888 | N43: 15234 | O43: 13107 | P43: 10536 | Q43: 7043 | R43: 4910 | S43: 3730 | T43: 2456 | U43: 2294 | V43: =SUM(E43:U43) -> 526874
... A71: TD20 | B71: Ennedi Est | C71: Ennedi Est | D71: Total | E71: 30620.131 | F71: 25674.186 | G71: 16080.713 | H71: 16133.751 | I71: 15317.095 | J71: 12888.214 | K71: 9782.62 | L71: 7599.7583 | M71: 5703.1736 | N71: 4590.6553 | O71: 4283.93 | P71: 3517.7558 | Q71: 2262.7381 | R71: 1490.8128 | S71: 1066.5094 | T71: 651.79126 | U71: 435.16652 | V71: =SUM(E71:U71) -> 158099
A72: TD | D72: Total | V72: =SUM(V5,V8,V11,V14,V17,V20,V23,V26,V29,V32,V35,V38,V41,V44,V47,V50,V53,V56,V59,V62,V65,V68,V71) -> 16344855

Sheet Admin1_Ndjam
A2: 2020
A3: admin1Pcode | B3: admin1Name_fr | C3: admin1RefName | D3: Sexe | E3: 0-4 | F3: 5-9 | G3: 10-14 | H3: 15-19 | I3: 20-24 | J3: 25-29 | K3: 30-34 | L3: 35-39 | M3: 40-44 | N3: 45-49 | O3: 50-54 | P3: 55-59 | Q3: 60-64 | R3: 65-69 | S3: 70-74 | T3: 75-79 | U3: 80+ | V3: Total
A4: TD18 | B4: N'Djamena | C4: NDjamena | D4: Femmes | E4: 153729 | F4: 126040 | G4: 103810 | H4: 92370 | I4: 67726 | J4: 52119 | K4: 46733 | L4: 39673 | M4: 30956 | N4: 24467 | O4: 18634 | P4: 13968 | Q4: 9997 | R4: 7070 | S4: 4975 | T4: 3126 | U4: 2608 | V4: =SUM(E4:U4) -> 798001
A5: TD18 | B5: N'Djamena | C5: NDjamena | D5: Hommes | E5: 165724 | F5: 123724 | G5: 108419 | H5: 96249 | I5: 70947 | J5: 52133 | K5: 37800 | L5: 29382 | M5: 25518 | N5: 21804 | O5: 18225 | P5: 14651 | Q5: 10832 | R5: 7802 | S5: 5129 | T5: 3113 | U5: 2805 | V5: =SUM(E5:U5) -> 794257
A6: TD18 | B6: N'Djamena | C6: NDjamena | D6: Total | E6: 316915 | F6: 259623 | G6: 210596 | H6: 187170 | I6: 137602 | J6: 103485 | K6: 84050 | L6: 68706 | M6: 56143 | N6: 45972 | O6: 36594 | P6: 28398 | Q6: 20662 | R6: 14751 | S6: 10028 | T6: 6194 | U6: 5370 | V6: =SUM(E6:U6) -> 1592259
A8: Structure 2020
A9: admin1Pcode | B9: admin1Name_fr | C9: admin1RefName | D9: Sexe | E9: 0-4 | F9: 5-9 | G9: 10-14 | H9: 15-19 | I9: 20-24 | J9: 25-29 | K9: 30-34 | L9: 35-39 | M9: 40-44 | N9: 45-49 | O9: 50-54 | P9: 55-59 | Q9: 60-64 | R9: 65-69 | S9: 70-74 | T9: 75-79 | U9: 80+ | V9: Total
A10: TD18 | B10: N'Djamena | C10: NDjamena | D10: Femmes | E10: =E4/$V$6 -> 0.096547735 | F10: =F4/$V$6 -> 0.079157976 | G10: =G4/$V$6 -> 0.06519668 | H10: =H4/$V$6 -> 0.058011919 | I10: =I4/$V$6 -> 0.042534537 | J10: =J4/$V$6 -> 0.03273274 | K10: =K4/$V$6 -> 0.029350125 | L10: =L4/$V$6 -> 0.024916173 | ... V10: =V4/$V$6 -> 0.50117537
A11: TD18 | B11: N'Djamena | C11: NDjamena | D11: Hommes | E11: =E5/$V$6 -> 0.10408106 | F11: =F5/$V$6 -> 0.077703439 | G11: =G5/$V$6 -> 0.068091309 | H11: =H5/$V$6 -> 0.06044808 | I11: =I5/$V$6 -> 0.04455745 | J11: =J5/$V$6 -> 0.032741533 | K11: =K5/$V$6 -> 0.023739856 | L11: =L5/$V$6 -> 0.018453028 | ... V11: =V5/$V$6 -> 0.498824
A12: TD18 | B12: N'Djamena | C12: NDjamena | D12: Total | E12: =E6/$V$6 -> 0.19903483 | F12: =F6/$V$6 -> 0.16305325 | G12: =G6/$V$6 -> 0.1322624 | H12: =H6/$V$6 -> 0.11754997 | I12: =I6/$V$6 -> 0.086419358 | J12: =J6/$V$6 -> 0.064992567 | K12: =K6/$V$6 -> 0.052786638 | L12: =L6/$V$6 -> 0.043150015 | ... V12: =V6/$V$6 -> 1
A14: Pop 2021
A15: admin1Pcode | B15: admin1Name_fr | C15: admin1RefName | D15: Sexe | E15: 0-4 | F15: 5-9 | G15: 10-14 | H15: 15-19 | I15: 20-24 | J15: 25-29 | K15: 30-34 | L15: 35-39 | M15: 40-44 | N15: 45-49 | O15: 50-54 | P15: 55-59 | Q15: 60-64 | R15: 65-69 | S15: 70-74 | T15: 75-79 | U15: 80+ | V15: Total
A16: TD18 | B16: N'Djamena | C16: NDjamena | D16: Femmes | E16: =E10*$V$20 -> 158182.72 | F16: =F10*$V$20 -> 129691.53 | G16: =G10*$V$20 -> 106817.5 | H16: =H10*$V$20 -> 95046.072 | I16: =I10*$V$20 -> 69688.105 | J16: =J10*$V$20 -> 53628.951 | K16: =K10*$V$20 -> 48086.912 | L16: =L10*$V$20 -> 40822.376 | ... V16: =V10*$V$20 -> 821120.07
A17: TD18 | B17: N'Djamena | C17: NDjamena | D17: Hommes | E17: =E11*$V$20 -> 170525.23 | F17: =F11*$V$20 -> 127308.44 | G17: =G11*$V$20 -> 111560.03 | H17: =H11*$V$20 -> 99037.452 | I17: =I11*$V$20 -> 73002.422 | J17: =J11*$V$20 -> 53643.357 | K17: =K11*$V$20 -> 38895.112 | L17: =L11*$V$20 -> 30233.233 | ... V17: =V11*$V$20 -> 817267.6
A18: TD18 | B18: N'Djamena | C18: NDjamena | D18: Total | E18: =E12*$V$20 -> 326096.42 | F18: =F12*$V$20 -> 267144.6 | G18: =G12*$V$20 -> 216697.22 | H18: =H12*$V$20 -> 192592.54 | I18: =I12*$V$20 -> 141588.5 | J18: =J12*$V$20 -> 106483.09 | K18: =K12*$V$20 -> 86485.032 | L18: =L12*$V$20 -> 70696.497 | ... V18: =V12*$V$20 -> 1638388.7
A20: Structure 2021 | V20: 1638388.7
A21: admin1Pcode | B21: admin1Name_fr | C21: admin1RefName | D21: Sexe | E21: 0-4 | F21: 5-9 | G21: 10-14 | H21: 15-19 | I21: 20-24 | J21: 25-29 | K21: 30-34 | L21: 35-39 | M21: 40-44 | N21: 45-49 | O21: 50-54 | P21: 55-59 | Q21: 60-64 | R21: 65-69 | S21: 70-74 | T21: 75-79 | U21: 80+ | V21: Total
A22: TD18 | B22: N'Djamena | C22: NDjamena | D22: Femmes | E22: =E16/$V$18 -> 0.096547735 | F22: =F16/$V$18 -> 0.079157976 | G22: =G16/$V$18 -> 0.06519668 | H22: =H16/$V$18 -> 0.058011919 | I22: =I16/$V$18 -> 0.042534537 | J22: =J16/$V$18 -> 0.03273274 | K22: =K16/$V$18 -> 0.029350125 | L22: =L16/$V$18 -> 0.024916173 | ... V22: =V16/$V$18 -> 0.50117537
A23: TD18 | B23: N'Djamena | C23: NDjamena | D23: Hommes | E23: =E17/$V$18 -> 0.10408106 | F23: =F17/$V$18 -> 0.077703439 | G23: =G17/$V$18 -> 0.068091309 | H23: =H17/$V$18 -> 0.06044808 | I23: =I17/$V$18 -> 0.04455745 | J23: =J17/$V$18 -> 0.032741533 | K23: =K17/$V$18 -> 0.023739856 | L23: =L17/$V$18 -> 0.018453028 | ... V23: =V17/$V$18 -> 0.498824
